Building DAG of jobs...
Using shell: /usr/bin/bash
Provided cores: 7
Rules claiming more threads will be scaled down.
Job counts:
	count	jobs
	1	all
	134	get_coords
	135

[Thu Nov 19 09:22:13 2020]
rule get_coords:
    input: data/starting_files/ENSSSCG00000006403
    output: data/gene_coords/ENSSSCG00000006403.gene, data/var_coords/ENSSSCG00000006403.vars
    jobid: 20
    wildcards: id=ENSSSCG00000006403

[Thu Nov 19 09:22:13 2020]
rule get_coords:
    input: data/starting_files/ENSSSCG00000010929
    output: data/gene_coords/ENSSSCG00000010929.gene, data/var_coords/ENSSSCG00000010929.vars
    jobid: 5
    wildcards: id=ENSSSCG00000010929

[Thu Nov 19 09:22:13 2020]
rule get_coords:
    input: data/starting_files/ENSSSCG00000009115
    output: data/gene_coords/ENSSSCG00000009115.gene, data/var_coords/ENSSSCG00000009115.vars
    jobid: 50
    wildcards: id=ENSSSCG00000009115

[Thu Nov 19 09:22:13 2020]
rule get_coords:
    input: data/starting_files/ENSSSCG00000017121
    output: data/gene_coords/ENSSSCG00000017121.gene, data/var_coords/ENSSSCG00000017121.vars
    jobid: 35
    wildcards: id=ENSSSCG00000017121

[Thu Nov 19 09:22:13 2020]
rule get_coords:
    input: data/starting_files/ENSSSCG00000008088
    output: data/gene_coords/ENSSSCG00000008088.gene, data/var_coords/ENSSSCG00000008088.vars
    jobid: 65
    wildcards: id=ENSSSCG00000008088

[Thu Nov 19 09:22:13 2020]
rule get_coords:
    input: data/starting_files/ENSSSCG00000023666
    output: data/gene_coords/ENSSSCG00000023666.gene, data/var_coords/ENSSSCG00000023666.vars
    jobid: 26
    wildcards: id=ENSSSCG00000023666

[Thu Nov 19 09:22:13 2020]
rule get_coords:
    input: data/starting_files/ENSSSCG00000012257
    output: data/gene_coords/ENSSSCG00000012257.gene, data/var_coords/ENSSSCG00000012257.vars
    jobid: 36
    wildcards: id=ENSSSCG00000012257

[Thu Nov 19 09:22:14 2020]
Error in rule get_coords:
    jobid: 65
    output: data/gene_coords/ENSSSCG00000008088.gene, data/var_coords/ENSSSCG00000008088.vars

RuleException:
CalledProcessError in line 18 of /home/pelmo/tesi/remap_sscrofa/Snakefile:
Command 'set -euo pipefail;  /home/pelmo/anaconda3/envs/snakemake/bin/python3.9 /home/pelmo/tesi/remap_sscrofa/.snakemake/scripts/tmpyvrf65e5.get_coords.py' returned non-zero exit status 1.
  File "/home/pelmo/anaconda3/envs/snakemake/lib/python3.9/site-packages/snakemake/executors/__init__.py", line 2231, in run_wrapper
  File "/home/pelmo/tesi/remap_sscrofa/Snakefile", line 18, in __rule_get_coords
  File "/home/pelmo/anaconda3/envs/snakemake/lib/python3.9/site-packages/snakemake/executors/__init__.py", line 560, in _callback
  File "/home/pelmo/anaconda3/envs/snakemake/lib/python3.9/concurrent/futures/thread.py", line 52, in run
  File "/home/pelmo/anaconda3/envs/snakemake/lib/python3.9/site-packages/snakemake/executors/__init__.py", line 546, in cached_or_run
  File "/home/pelmo/anaconda3/envs/snakemake/lib/python3.9/site-packages/snakemake/executors/__init__.py", line 2262, in run_wrapper
[Thu Nov 19 09:22:14 2020]
Error in rule get_coords:
    jobid: 36
    output: data/gene_coords/ENSSSCG00000012257.gene, data/var_coords/ENSSSCG00000012257.vars

RuleException:
CalledProcessError in line 18 of /home/pelmo/tesi/remap_sscrofa/Snakefile:
Command 'set -euo pipefail;  /home/pelmo/anaconda3/envs/snakemake/bin/python3.9 /home/pelmo/tesi/remap_sscrofa/.snakemake/scripts/tmpf3tg8l2w.get_coords.py' returned non-zero exit status 1.
  File "/home/pelmo/anaconda3/envs/snakemake/lib/python3.9/site-packages/snakemake/executors/__init__.py", line 2231, in run_wrapper
  File "/home/pelmo/tesi/remap_sscrofa/Snakefile", line 18, in __rule_get_coords
  File "/home/pelmo/anaconda3/envs/snakemake/lib/python3.9/site-packages/snakemake/executors/__init__.py", line 560, in _callback
  File "/home/pelmo/anaconda3/envs/snakemake/lib/python3.9/concurrent/futures/thread.py", line 52, in run
  File "/home/pelmo/anaconda3/envs/snakemake/lib/python3.9/site-packages/snakemake/executors/__init__.py", line 546, in cached_or_run
  File "/home/pelmo/anaconda3/envs/snakemake/lib/python3.9/site-packages/snakemake/executors/__init__.py", line 2262, in run_wrapper
[Thu Nov 19 09:22:14 2020]
Error in rule get_coords:
    jobid: 35
    output: data/gene_coords/ENSSSCG00000017121.gene, data/var_coords/ENSSSCG00000017121.vars

[Thu Nov 19 09:22:14 2020]
[Thu Nov 19 09:22:14 2020]
Error in rule get_coords:
Error in rule get_coords:
    jobid: 26
    jobid: 5
[Thu Nov 19 09:22:14 2020]
RuleException:
CalledProcessError in line 18 of /home/pelmo/tesi/remap_sscrofa/Snakefile:
Command 'set -euo pipefail;  /home/pelmo/anaconda3/envs/snakemake/bin/python3.9 /home/pelmo/tesi/remap_sscrofa/.snakemake/scripts/tmpxblnr81h.get_coords.py' returned non-zero exit status 1.
  File "/home/pelmo/anaconda3/envs/snakemake/lib/python3.9/site-packages/snakemake/executors/__init__.py", line 2231, in run_wrapper
  File "/home/pelmo/tesi/remap_sscrofa/Snakefile", line 18, in __rule_get_coords
  File "/home/pelmo/anaconda3/envs/snakemake/lib/python3.9/site-packages/snakemake/executors/__init__.py", line 560, in _callback
  File "/home/pelmo/anaconda3/envs/snakemake/lib/python3.9/concurrent/futures/thread.py", line 52, in run
  File "/home/pelmo/anaconda3/envs/snakemake/lib/python3.9/site-packages/snakemake/executors/__init__.py", line 546, in cached_or_run
  File "/home/pelmo/anaconda3/envs/snakemake/lib/python3.9/site-packages/snakemake/executors/__init__.py", line 2262, in run_wrapper
    output: data/gene_coords/ENSSSCG00000023666.gene, data/var_coords/ENSSSCG00000023666.vars
[Thu Nov 19 09:22:14 2020]
    output: data/gene_coords/ENSSSCG00000010929.gene, data/var_coords/ENSSSCG00000010929.vars
Error in rule get_coords:

Error in rule get_coords:

    jobid: 50
    jobid: 20
RuleException:
CalledProcessError in line 18 of /home/pelmo/tesi/remap_sscrofa/Snakefile:
Command 'set -euo pipefail;  /home/pelmo/anaconda3/envs/snakemake/bin/python3.9 /home/pelmo/tesi/remap_sscrofa/.snakemake/scripts/tmplvc0b55d.get_coords.py' returned non-zero exit status 1.
  File "/home/pelmo/anaconda3/envs/snakemake/lib/python3.9/site-packages/snakemake/executors/__init__.py", line 2231, in run_wrapper
  File "/home/pelmo/tesi/remap_sscrofa/Snakefile", line 18, in __rule_get_coords
  File "/home/pelmo/anaconda3/envs/snakemake/lib/python3.9/site-packages/snakemake/executors/__init__.py", line 560, in _callback
  File "/home/pelmo/anaconda3/envs/snakemake/lib/python3.9/concurrent/futures/thread.py", line 52, in run
  File "/home/pelmo/anaconda3/envs/snakemake/lib/python3.9/site-packages/snakemake/executors/__init__.py", line 546, in cached_or_run
  File "/home/pelmo/anaconda3/envs/snakemake/lib/python3.9/site-packages/snakemake/executors/__init__.py", line 2262, in run_wrapper
    output: data/gene_coords/ENSSSCG00000009115.gene, data/var_coords/ENSSSCG00000009115.vars
    output: data/gene_coords/ENSSSCG00000006403.gene, data/var_coords/ENSSSCG00000006403.vars
RuleException:
CalledProcessError in line 18 of /home/pelmo/tesi/remap_sscrofa/Snakefile:
Command 'set -euo pipefail;  /home/pelmo/anaconda3/envs/snakemake/bin/python3.9 /home/pelmo/tesi/remap_sscrofa/.snakemake/scripts/tmpgdr74nfm.get_coords.py' returned non-zero exit status 1.
  File "/home/pelmo/anaconda3/envs/snakemake/lib/python3.9/site-packages/snakemake/executors/__init__.py", line 2231, in run_wrapper
  File "/home/pelmo/tesi/remap_sscrofa/Snakefile", line 18, in __rule_get_coords
  File "/home/pelmo/anaconda3/envs/snakemake/lib/python3.9/site-packages/snakemake/executors/__init__.py", line 560, in _callback
  File "/home/pelmo/anaconda3/envs/snakemake/lib/python3.9/concurrent/futures/thread.py", line 52, in run
  File "/home/pelmo/anaconda3/envs/snakemake/lib/python3.9/site-packages/snakemake/executors/__init__.py", line 546, in cached_or_run
  File "/home/pelmo/anaconda3/envs/snakemake/lib/python3.9/site-packages/snakemake/executors/__init__.py", line 2262, in run_wrapper


RuleException:
CalledProcessError in line 18 of /home/pelmo/tesi/remap_sscrofa/Snakefile:
Command 'set -euo pipefail;  /home/pelmo/anaconda3/envs/snakemake/bin/python3.9 /home/pelmo/tesi/remap_sscrofa/.snakemake/scripts/tmpvnk2c5nx.get_coords.py' returned non-zero exit status 1.
  File "/home/pelmo/anaconda3/envs/snakemake/lib/python3.9/site-packages/snakemake/executors/__init__.py", line 2231, in run_wrapper
  File "/home/pelmo/tesi/remap_sscrofa/Snakefile", line 18, in __rule_get_coords
  File "/home/pelmo/anaconda3/envs/snakemake/lib/python3.9/site-packages/snakemake/executors/__init__.py", line 560, in _callback
  File "/home/pelmo/anaconda3/envs/snakemake/lib/python3.9/concurrent/futures/thread.py", line 52, in run
  File "/home/pelmo/anaconda3/envs/snakemake/lib/python3.9/site-packages/snakemake/executors/__init__.py", line 546, in cached_or_run
  File "/home/pelmo/anaconda3/envs/snakemake/lib/python3.9/site-packages/snakemake/executors/__init__.py", line 2262, in run_wrapper
RuleException:
CalledProcessError in line 18 of /home/pelmo/tesi/remap_sscrofa/Snakefile:
Command 'set -euo pipefail;  /home/pelmo/anaconda3/envs/snakemake/bin/python3.9 /home/pelmo/tesi/remap_sscrofa/.snakemake/scripts/tmp3h85jx6x.get_coords.py' returned non-zero exit status 1.
  File "/home/pelmo/anaconda3/envs/snakemake/lib/python3.9/site-packages/snakemake/executors/__init__.py", line 2231, in run_wrapper
  File "/home/pelmo/tesi/remap_sscrofa/Snakefile", line 18, in __rule_get_coords
  File "/home/pelmo/anaconda3/envs/snakemake/lib/python3.9/site-packages/snakemake/executors/__init__.py", line 560, in _callback
  File "/home/pelmo/anaconda3/envs/snakemake/lib/python3.9/concurrent/futures/thread.py", line 52, in run
  File "/home/pelmo/anaconda3/envs/snakemake/lib/python3.9/site-packages/snakemake/executors/__init__.py", line 546, in cached_or_run
  File "/home/pelmo/anaconda3/envs/snakemake/lib/python3.9/site-packages/snakemake/executors/__init__.py", line 2262, in run_wrapper
Shutting down, this might take some time.
Exiting because a job execution failed. Look above for error message
Complete log: /home/pelmo/tesi/remap_sscrofa/.snakemake/log/2020-11-19T092213.212985.snakemake.log
