Building DAG of jobs...
Using shell: /usr/bin/bash
Provided cores: 7
Rules claiming more threads will be scaled down.
Job counts:
	count	jobs
	1	all
	134	get_coords
	135

[Thu Nov 19 09:30:27 2020]
rule get_coords:
    input: data/starting_files/ENSSSCG00000017121
    output: data/gene_coords/ENSSSCG00000017121.gene, data/var_coords/ENSSSCG00000017121.vars
    jobid: 35
    wildcards: id=ENSSSCG00000017121

[Thu Nov 19 09:30:27 2020]
rule get_coords:
    input: data/starting_files/ENSSSCG00000009115
    output: data/gene_coords/ENSSSCG00000009115.gene, data/var_coords/ENSSSCG00000009115.vars
    jobid: 50
    wildcards: id=ENSSSCG00000009115

[Thu Nov 19 09:30:27 2020]
rule get_coords:
    input: data/starting_files/ENSSSCG00000006403
    output: data/gene_coords/ENSSSCG00000006403.gene, data/var_coords/ENSSSCG00000006403.vars
    jobid: 20
    wildcards: id=ENSSSCG00000006403

[Thu Nov 19 09:30:27 2020]
rule get_coords:
    input: data/starting_files/ENSSSCG00000008088
    output: data/gene_coords/ENSSSCG00000008088.gene, data/var_coords/ENSSSCG00000008088.vars
    jobid: 65
    wildcards: id=ENSSSCG00000008088

[Thu Nov 19 09:30:27 2020]
rule get_coords:
    input: data/starting_files/ENSSSCG00000001741
    output: data/gene_coords/ENSSSCG00000001741.gene, data/var_coords/ENSSSCG00000001741.vars
    jobid: 95
    wildcards: id=ENSSSCG00000001741

[Thu Nov 19 09:30:27 2020]
rule get_coords:
    input: data/starting_files/ENSSSCG00000023666
    output: data/gene_coords/ENSSSCG00000023666.gene, data/var_coords/ENSSSCG00000023666.vars
    jobid: 26
    wildcards: id=ENSSSCG00000023666

[Thu Nov 19 09:30:27 2020]
rule get_coords:
    input: data/starting_files/ENSSSCG00000026201
    output: data/gene_coords/ENSSSCG00000026201.gene, data/var_coords/ENSSSCG00000026201.vars
    jobid: 21
    wildcards: id=ENSSSCG00000026201

[Thu Nov 19 09:30:28 2020]
Error in rule get_coords:
    jobid: 20
    output: data/gene_coords/ENSSSCG00000006403.gene, data/var_coords/ENSSSCG00000006403.vars

RuleException:
CalledProcessError in line 18 of /home/pelmo/tesi/remap_sscrofa/Snakefile:
Command 'set -euo pipefail;  /home/pelmo/anaconda3/envs/snakemake/bin/python3.9 /home/pelmo/tesi/remap_sscrofa/.snakemake/scripts/tmpn__wi04u.get_coords.py' returned non-zero exit status 1.
  File "/home/pelmo/anaconda3/envs/snakemake/lib/python3.9/site-packages/snakemake/executors/__init__.py", line 2231, in run_wrapper
  File "/home/pelmo/tesi/remap_sscrofa/Snakefile", line 18, in __rule_get_coords
  File "/home/pelmo/anaconda3/envs/snakemake/lib/python3.9/site-packages/snakemake/executors/__init__.py", line 560, in _callback
  File "/home/pelmo/anaconda3/envs/snakemake/lib/python3.9/concurrent/futures/thread.py", line 52, in run
  File "/home/pelmo/anaconda3/envs/snakemake/lib/python3.9/site-packages/snakemake/executors/__init__.py", line 546, in cached_or_run
  File "/home/pelmo/anaconda3/envs/snakemake/lib/python3.9/site-packages/snakemake/executors/__init__.py", line 2262, in run_wrapper
[Thu Nov 19 09:30:28 2020]
Error in rule get_coords:
    jobid: 50
    output: data/gene_coords/ENSSSCG00000009115.gene, data/var_coords/ENSSSCG00000009115.vars

[Thu Nov 19 09:30:28 2020]
RuleException:
CalledProcessError in line 18 of /home/pelmo/tesi/remap_sscrofa/Snakefile:
Command 'set -euo pipefail;  /home/pelmo/anaconda3/envs/snakemake/bin/python3.9 /home/pelmo/tesi/remap_sscrofa/.snakemake/scripts/tmp4c5ecpsz.get_coords.py' returned non-zero exit status 1.
  File "/home/pelmo/anaconda3/envs/snakemake/lib/python3.9/site-packages/snakemake/executors/__init__.py", line 2231, in run_wrapper
  File "/home/pelmo/tesi/remap_sscrofa/Snakefile", line 18, in __rule_get_coords
  File "/home/pelmo/anaconda3/envs/snakemake/lib/python3.9/site-packages/snakemake/executors/__init__.py", line 560, in _callback
  File "/home/pelmo/anaconda3/envs/snakemake/lib/python3.9/concurrent/futures/thread.py", line 52, in run
  File "/home/pelmo/anaconda3/envs/snakemake/lib/python3.9/site-packages/snakemake/executors/__init__.py", line 546, in cached_or_run
  File "/home/pelmo/anaconda3/envs/snakemake/lib/python3.9/site-packages/snakemake/executors/__init__.py", line 2262, in run_wrapper
Error in rule get_coords:
    jobid: 26
    output: data/gene_coords/ENSSSCG00000023666.gene, data/var_coords/ENSSSCG00000023666.vars

RuleException:
CalledProcessError in line 18 of /home/pelmo/tesi/remap_sscrofa/Snakefile:
Command 'set -euo pipefail;  /home/pelmo/anaconda3/envs/snakemake/bin/python3.9 /home/pelmo/tesi/remap_sscrofa/.snakemake/scripts/tmpsxsbj9sx.get_coords.py' returned non-zero exit status 1.
  File "/home/pelmo/anaconda3/envs/snakemake/lib/python3.9/site-packages/snakemake/executors/__init__.py", line 2231, in run_wrapper
  File "/home/pelmo/tesi/remap_sscrofa/Snakefile", line 18, in __rule_get_coords
  File "/home/pelmo/anaconda3/envs/snakemake/lib/python3.9/site-packages/snakemake/executors/__init__.py", line 560, in _callback
  File "/home/pelmo/anaconda3/envs/snakemake/lib/python3.9/concurrent/futures/thread.py", line 52, in run
  File "/home/pelmo/anaconda3/envs/snakemake/lib/python3.9/site-packages/snakemake/executors/__init__.py", line 546, in cached_or_run
  File "/home/pelmo/anaconda3/envs/snakemake/lib/python3.9/site-packages/snakemake/executors/__init__.py", line 2262, in run_wrapper
[Thu Nov 19 09:30:28 2020]
Error in rule get_coords:
    jobid: 35
    output: data/gene_coords/ENSSSCG00000017121.gene, data/var_coords/ENSSSCG00000017121.vars

RuleException:
CalledProcessError in line 18 of /home/pelmo/tesi/remap_sscrofa/Snakefile:
Command 'set -euo pipefail;  /home/pelmo/anaconda3/envs/snakemake/bin/python3.9 /home/pelmo/tesi/remap_sscrofa/.snakemake/scripts/tmpaakdjmn_.get_coords.py' returned non-zero exit status 1.
  File "/home/pelmo/anaconda3/envs/snakemake/lib/python3.9/site-packages/snakemake/executors/__init__.py", line 2231, in run_wrapper
  File "/home/pelmo/tesi/remap_sscrofa/Snakefile", line 18, in __rule_get_coords
  File "/home/pelmo/anaconda3/envs/snakemake/lib/python3.9/site-packages/snakemake/executors/__init__.py", line 560, in _callback
  File "/home/pelmo/anaconda3/envs/snakemake/lib/python3.9/concurrent/futures/thread.py", line 52, in run
  File "/home/pelmo/anaconda3/envs/snakemake/lib/python3.9/site-packages/snakemake/executors/__init__.py", line 546, in cached_or_run
  File "/home/pelmo/anaconda3/envs/snakemake/lib/python3.9/site-packages/snakemake/executors/__init__.py", line 2262, in run_wrapper
[Thu Nov 19 09:30:28 2020]
Error in rule get_coords:
    jobid: 21
    output: data/gene_coords/ENSSSCG00000026201.gene, data/var_coords/ENSSSCG00000026201.vars

RuleException:
CalledProcessError in line 18 of /home/pelmo/tesi/remap_sscrofa/Snakefile:
Command 'set -euo pipefail;  /home/pelmo/anaconda3/envs/snakemake/bin/python3.9 /home/pelmo/tesi/remap_sscrofa/.snakemake/scripts/tmp1o281yie.get_coords.py' returned non-zero exit status 1.
  File "/home/pelmo/anaconda3/envs/snakemake/lib/python3.9/site-packages/snakemake/executors/__init__.py", line 2231, in run_wrapper
  File "/home/pelmo/tesi/remap_sscrofa/Snakefile", line 18, in __rule_get_coords
  File "/home/pelmo/anaconda3/envs/snakemake/lib/python3.9/site-packages/snakemake/executors/__init__.py", line 560, in _callback
  File "/home/pelmo/anaconda3/envs/snakemake/lib/python3.9/concurrent/futures/thread.py", line 52, in run
  File "/home/pelmo/anaconda3/envs/snakemake/lib/python3.9/site-packages/snakemake/executors/__init__.py", line 546, in cached_or_run
  File "/home/pelmo/anaconda3/envs/snakemake/lib/python3.9/site-packages/snakemake/executors/__init__.py", line 2262, in run_wrapper
[Thu Nov 19 09:30:28 2020]
Error in rule get_coords:
    jobid: 65
    output: data/gene_coords/ENSSSCG00000008088.gene, data/var_coords/ENSSSCG00000008088.vars

RuleException:
CalledProcessError in line 18 of /home/pelmo/tesi/remap_sscrofa/Snakefile:
Command 'set -euo pipefail;  /home/pelmo/anaconda3/envs/snakemake/bin/python3.9 /home/pelmo/tesi/remap_sscrofa/.snakemake/scripts/tmp24qisj09.get_coords.py' returned non-zero exit status 1.
  File "/home/pelmo/anaconda3/envs/snakemake/lib/python3.9/site-packages/snakemake/executors/__init__.py", line 2231, in run_wrapper
  File "/home/pelmo/tesi/remap_sscrofa/Snakefile", line 18, in __rule_get_coords
  File "/home/pelmo/anaconda3/envs/snakemake/lib/python3.9/site-packages/snakemake/executors/__init__.py", line 560, in _callback
  File "/home/pelmo/anaconda3/envs/snakemake/lib/python3.9/concurrent/futures/thread.py", line 52, in run
  File "/home/pelmo/anaconda3/envs/snakemake/lib/python3.9/site-packages/snakemake/executors/__init__.py", line 546, in cached_or_run
  File "/home/pelmo/anaconda3/envs/snakemake/lib/python3.9/site-packages/snakemake/executors/__init__.py", line 2262, in run_wrapper
[Thu Nov 19 09:30:28 2020]
Error in rule get_coords:
    jobid: 95
    output: data/gene_coords/ENSSSCG00000001741.gene, data/var_coords/ENSSSCG00000001741.vars

RuleException:
CalledProcessError in line 18 of /home/pelmo/tesi/remap_sscrofa/Snakefile:
Command 'set -euo pipefail;  /home/pelmo/anaconda3/envs/snakemake/bin/python3.9 /home/pelmo/tesi/remap_sscrofa/.snakemake/scripts/tmpxfm41wsz.get_coords.py' returned non-zero exit status 1.
  File "/home/pelmo/anaconda3/envs/snakemake/lib/python3.9/site-packages/snakemake/executors/__init__.py", line 2231, in run_wrapper
  File "/home/pelmo/tesi/remap_sscrofa/Snakefile", line 18, in __rule_get_coords
  File "/home/pelmo/anaconda3/envs/snakemake/lib/python3.9/site-packages/snakemake/executors/__init__.py", line 560, in _callback
  File "/home/pelmo/anaconda3/envs/snakemake/lib/python3.9/concurrent/futures/thread.py", line 52, in run
  File "/home/pelmo/anaconda3/envs/snakemake/lib/python3.9/site-packages/snakemake/executors/__init__.py", line 546, in cached_or_run
  File "/home/pelmo/anaconda3/envs/snakemake/lib/python3.9/site-packages/snakemake/executors/__init__.py", line 2262, in run_wrapper
Shutting down, this might take some time.
Exiting because a job execution failed. Look above for error message
Complete log: /home/pelmo/tesi/remap_sscrofa/.snakemake/log/2020-11-19T093027.600827.snakemake.log
