Building DAG of jobs...
Using shell: /usr/bin/bash
Provided cores: 7
Rules claiming more threads will be scaled down.
Job counts:
	count	jobs
	1	all
	134	get_coords
	135

[Thu Nov 19 09:46:31 2020]
rule get_coords:
    input: data/starting_files/ENSSSCG00000009115
    output: data/gene_coords/ENSSSCG00000009115.gene, data/var_coords/ENSSSCG00000009115.vars
    jobid: 50
    wildcards: id=ENSSSCG00000009115

[Thu Nov 19 09:46:31 2020]
rule get_coords:
    input: data/starting_files/ENSSSCG00000017121
    output: data/gene_coords/ENSSSCG00000017121.gene, data/var_coords/ENSSSCG00000017121.vars
    jobid: 35
    wildcards: id=ENSSSCG00000017121

[Thu Nov 19 09:46:31 2020]
rule get_coords:
    input: data/starting_files/ENSSSCG00000030168
    output: data/gene_coords/ENSSSCG00000030168.gene, data/var_coords/ENSSSCG00000030168.vars
    jobid: 80
    wildcards: id=ENSSSCG00000030168

[Thu Nov 19 09:46:31 2020]
rule get_coords:
    input: data/starting_files/ENSSSCG00000008088
    output: data/gene_coords/ENSSSCG00000008088.gene, data/var_coords/ENSSSCG00000008088.vars
    jobid: 65
    wildcards: id=ENSSSCG00000008088

[Thu Nov 19 09:46:31 2020]
rule get_coords:
    input: data/starting_files/ENSSSCG00000010591
    output: data/gene_coords/ENSSSCG00000010591.gene, data/var_coords/ENSSSCG00000010591.vars
    jobid: 110
    wildcards: id=ENSSSCG00000010591

[Thu Nov 19 09:46:31 2020]
rule get_coords:
    input: data/starting_files/ENSSSCG00000023666
    output: data/gene_coords/ENSSSCG00000023666.gene, data/var_coords/ENSSSCG00000023666.vars
    jobid: 26
    wildcards: id=ENSSSCG00000023666

[Thu Nov 19 09:46:31 2020]
rule get_coords:
    input: data/starting_files/ENSSSCG00000007522
    output: data/gene_coords/ENSSSCG00000007522.gene, data/var_coords/ENSSSCG00000007522.vars
    jobid: 66
    wildcards: id=ENSSSCG00000007522

[Thu Nov 19 09:46:32 2020]
Error in rule get_coords:
    jobid: 66
    output: data/gene_coords/ENSSSCG00000007522.gene, data/var_coords/ENSSSCG00000007522.vars

RuleException:
CalledProcessError in line 18 of /home/pelmo/tesi/remap_sscrofa/Snakefile:
Command 'set -euo pipefail;  /home/pelmo/anaconda3/envs/snakemake/bin/python3.9 /home/pelmo/tesi/remap_sscrofa/.snakemake/scripts/tmp6wd2d9fi.get_coords.py' returned non-zero exit status 1.
  File "/home/pelmo/anaconda3/envs/snakemake/lib/python3.9/site-packages/snakemake/executors/__init__.py", line 2231, in run_wrapper
  File "/home/pelmo/tesi/remap_sscrofa/Snakefile", line 18, in __rule_get_coords
  File "/home/pelmo/anaconda3/envs/snakemake/lib/python3.9/site-packages/snakemake/executors/__init__.py", line 560, in _callback
  File "/home/pelmo/anaconda3/envs/snakemake/lib/python3.9/concurrent/futures/thread.py", line 52, in run
  File "/home/pelmo/anaconda3/envs/snakemake/lib/python3.9/site-packages/snakemake/executors/__init__.py", line 546, in cached_or_run
  File "/home/pelmo/anaconda3/envs/snakemake/lib/python3.9/site-packages/snakemake/executors/__init__.py", line 2262, in run_wrapper
[Thu Nov 19 09:46:32 2020]
Error in rule get_coords:
    jobid: 35
    output: data/gene_coords/ENSSSCG00000017121.gene, data/var_coords/ENSSSCG00000017121.vars

RuleException:
CalledProcessError in line 18 of /home/pelmo/tesi/remap_sscrofa/Snakefile:
Command 'set -euo pipefail;  /home/pelmo/anaconda3/envs/snakemake/bin/python3.9 /home/pelmo/tesi/remap_sscrofa/.snakemake/scripts/tmpzeyd2bzi.get_coords.py' returned non-zero exit status 1.
  File "/home/pelmo/anaconda3/envs/snakemake/lib/python3.9/site-packages/snakemake/executors/__init__.py", line 2231, in run_wrapper
  File "/home/pelmo/tesi/remap_sscrofa/Snakefile", line 18, in __rule_get_coords
  File "/home/pelmo/anaconda3/envs/snakemake/lib/python3.9/site-packages/snakemake/executors/__init__.py", line 560, in _callback
  File "/home/pelmo/anaconda3/envs/snakemake/lib/python3.9/concurrent/futures/thread.py", line 52, in run
  File "/home/pelmo/anaconda3/envs/snakemake/lib/python3.9/site-packages/snakemake/executors/__init__.py", line 546, in cached_or_run
  File "/home/pelmo/anaconda3/envs/snakemake/lib/python3.9/site-packages/snakemake/executors/__init__.py", line 2262, in run_wrapper
[Thu Nov 19 09:46:32 2020]
Error in rule get_coords:
    jobid: 65
    output: data/gene_coords/ENSSSCG00000008088.gene, data/var_coords/ENSSSCG00000008088.vars

RuleException:
CalledProcessError in line 18 of /home/pelmo/tesi/remap_sscrofa/Snakefile:
Command 'set -euo pipefail;  /home/pelmo/anaconda3/envs/snakemake/bin/python3.9 /home/pelmo/tesi/remap_sscrofa/.snakemake/scripts/tmpq85qb00m.get_coords.py' returned non-zero exit status 1.
  File "/home/pelmo/anaconda3/envs/snakemake/lib/python3.9/site-packages/snakemake/executors/__init__.py", line 2231, in run_wrapper
  File "/home/pelmo/tesi/remap_sscrofa/Snakefile", line 18, in __rule_get_coords
  File "/home/pelmo/anaconda3/envs/snakemake/lib/python3.9/site-packages/snakemake/executors/__init__.py", line 560, in _callback
  File "/home/pelmo/anaconda3/envs/snakemake/lib/python3.9/concurrent/futures/thread.py", line 52, in run
  File "/home/pelmo/anaconda3/envs/snakemake/lib/python3.9/site-packages/snakemake/executors/__init__.py", line 546, in cached_or_run
  File "/home/pelmo/anaconda3/envs/snakemake/lib/python3.9/site-packages/snakemake/executors/__init__.py", line 2262, in run_wrapper
[Thu Nov 19 09:46:32 2020]
Error in rule get_coords:
    jobid: 110
    output: data/gene_coords/ENSSSCG00000010591.gene, data/var_coords/ENSSSCG00000010591.vars

RuleException:
CalledProcessError in line 18 of /home/pelmo/tesi/remap_sscrofa/Snakefile:
Command 'set -euo pipefail;  /home/pelmo/anaconda3/envs/snakemake/bin/python3.9 /home/pelmo/tesi/remap_sscrofa/.snakemake/scripts/tmp8zqf30wv.get_coords.py' returned non-zero exit status 1.
  File "/home/pelmo/anaconda3/envs/snakemake/lib/python3.9/site-packages/snakemake/executors/__init__.py", line 2231, in run_wrapper
  File "/home/pelmo/tesi/remap_sscrofa/Snakefile", line 18, in __rule_get_coords
  File "/home/pelmo/anaconda3/envs/snakemake/lib/python3.9/site-packages/snakemake/executors/__init__.py", line 560, in _callback
  File "/home/pelmo/anaconda3/envs/snakemake/lib/python3.9/concurrent/futures/thread.py", line 52, in run
  File "/home/pelmo/anaconda3/envs/snakemake/lib/python3.9/site-packages/snakemake/executors/__init__.py", line 546, in cached_or_run
  File "/home/pelmo/anaconda3/envs/snakemake/lib/python3.9/site-packages/snakemake/executors/__init__.py", line 2262, in run_wrapper
[Thu Nov 19 09:46:32 2020]
Error in rule get_coords:
    jobid: 80
    output: data/gene_coords/ENSSSCG00000030168.gene, data/var_coords/ENSSSCG00000030168.vars

RuleException:
CalledProcessError in line 18 of /home/pelmo/tesi/remap_sscrofa/Snakefile:
Command 'set -euo pipefail;  /home/pelmo/anaconda3/envs/snakemake/bin/python3.9 /home/pelmo/tesi/remap_sscrofa/.snakemake/scripts/tmp5bvr22f_.get_coords.py' returned non-zero exit status 1.
  File "/home/pelmo/anaconda3/envs/snakemake/lib/python3.9/site-packages/snakemake/executors/__init__.py", line 2231, in run_wrapper
  File "/home/pelmo/tesi/remap_sscrofa/Snakefile", line 18, in __rule_get_coords
  File "/home/pelmo/anaconda3/envs/snakemake/lib/python3.9/site-packages/snakemake/executors/__init__.py", line 560, in _callback
  File "/home/pelmo/anaconda3/envs/snakemake/lib/python3.9/concurrent/futures/thread.py", line 52, in run
  File "/home/pelmo/anaconda3/envs/snakemake/lib/python3.9/site-packages/snakemake/executors/__init__.py", line 546, in cached_or_run
  File "/home/pelmo/anaconda3/envs/snakemake/lib/python3.9/site-packages/snakemake/executors/__init__.py", line 2262, in run_wrapper
[Thu Nov 19 09:46:32 2020]
Error in rule get_coords:
    jobid: 26
    output: data/gene_coords/ENSSSCG00000023666.gene, data/var_coords/ENSSSCG00000023666.vars

[Thu Nov 19 09:46:32 2020]
Error in rule get_coords:
    jobid: 50
    output: data/gene_coords/ENSSSCG00000009115.gene, data/var_coords/ENSSSCG00000009115.vars

RuleException:
CalledProcessError in line 18 of /home/pelmo/tesi/remap_sscrofa/Snakefile:
Command 'set -euo pipefail;  /home/pelmo/anaconda3/envs/snakemake/bin/python3.9 /home/pelmo/tesi/remap_sscrofa/.snakemake/scripts/tmpeogaz0f_.get_coords.py' returned non-zero exit status 1.
  File "/home/pelmo/anaconda3/envs/snakemake/lib/python3.9/site-packages/snakemake/executors/__init__.py", line 2231, in run_wrapper
  File "/home/pelmo/tesi/remap_sscrofa/Snakefile", line 18, in __rule_get_coords
  File "/home/pelmo/anaconda3/envs/snakemake/lib/python3.9/site-packages/snakemake/executors/__init__.py", line 560, in _callback
  File "/home/pelmo/anaconda3/envs/snakemake/lib/python3.9/concurrent/futures/thread.py", line 52, in run
  File "/home/pelmo/anaconda3/envs/snakemake/lib/python3.9/site-packages/snakemake/executors/__init__.py", line 546, in cached_or_run
  File "/home/pelmo/anaconda3/envs/snakemake/lib/python3.9/site-packages/snakemake/executors/__init__.py", line 2262, in run_wrapper
RuleException:
CalledProcessError in line 18 of /home/pelmo/tesi/remap_sscrofa/Snakefile:
Command 'set -euo pipefail;  /home/pelmo/anaconda3/envs/snakemake/bin/python3.9 /home/pelmo/tesi/remap_sscrofa/.snakemake/scripts/tmpmuxe3jbu.get_coords.py' returned non-zero exit status 1.
  File "/home/pelmo/anaconda3/envs/snakemake/lib/python3.9/site-packages/snakemake/executors/__init__.py", line 2231, in run_wrapper
  File "/home/pelmo/tesi/remap_sscrofa/Snakefile", line 18, in __rule_get_coords
  File "/home/pelmo/anaconda3/envs/snakemake/lib/python3.9/site-packages/snakemake/executors/__init__.py", line 560, in _callback
  File "/home/pelmo/anaconda3/envs/snakemake/lib/python3.9/concurrent/futures/thread.py", line 52, in run
  File "/home/pelmo/anaconda3/envs/snakemake/lib/python3.9/site-packages/snakemake/executors/__init__.py", line 546, in cached_or_run
  File "/home/pelmo/anaconda3/envs/snakemake/lib/python3.9/site-packages/snakemake/executors/__init__.py", line 2262, in run_wrapper
Shutting down, this might take some time.
Exiting because a job execution failed. Look above for error message
Complete log: /home/pelmo/tesi/remap_sscrofa/.snakemake/log/2020-11-19T094631.622359.snakemake.log
