Building DAG of jobs...
Using shell: /usr/bin/bash
Provided cores: 7
Rules claiming more threads will be scaled down.
Job counts:
	count	jobs
	1	all
	134	get_coords
	135

[Thu Nov 19 09:25:28 2020]
rule get_coords:
    input: data/starting_files/ENSSSCG00000014428
    output: data/gene_coords/ENSSSCG00000014428.gene, data/var_coords/ENSSSCG00000014428.vars
    jobid: 27
    wildcards: id=ENSSSCG00000014428

[Thu Nov 19 09:25:28 2020]
rule get_coords:
    input: data/starting_files/ENSSSCG00000002756
    output: data/gene_coords/ENSSSCG00000002756.gene, data/var_coords/ENSSSCG00000002756.vars
    jobid: 86
    wildcards: id=ENSSSCG00000002756

[Thu Nov 19 09:25:28 2020]
rule get_coords:
    input: data/starting_files/ENSSSCG00000023666
    output: data/gene_coords/ENSSSCG00000023666.gene, data/var_coords/ENSSSCG00000023666.vars
    jobid: 26
    wildcards: id=ENSSSCG00000023666

[Thu Nov 19 09:25:28 2020]
rule get_coords:
    input: data/starting_files/ENSSSCG00000007218
    output: data/gene_coords/ENSSSCG00000007218.gene, data/var_coords/ENSSSCG00000007218.vars
    jobid: 116
    wildcards: id=ENSSSCG00000007218

[Thu Nov 19 09:25:28 2020]
rule get_coords:
    input: data/starting_files/ENSSSCG00000020924
    output: data/gene_coords/ENSSSCG00000020924.gene, data/var_coords/ENSSSCG00000020924.vars
    jobid: 56
    wildcards: id=ENSSSCG00000020924

[Thu Nov 19 09:25:28 2020]
rule get_coords:
    input: data/starting_files/ENSSSCG00000031002
    output: data/gene_coords/ENSSSCG00000031002.gene, data/var_coords/ENSSSCG00000031002.vars
    jobid: 11
    wildcards: id=ENSSSCG00000031002

[Thu Nov 19 09:25:28 2020]
rule get_coords:
    input: data/starting_files/ENSSSCG00000011436
    output: data/gene_coords/ENSSSCG00000011436.gene, data/var_coords/ENSSSCG00000011436.vars
    jobid: 41
    wildcards: id=ENSSSCG00000011436

[Thu Nov 19 09:25:28 2020]
Error in rule get_coords:
    jobid: 26
    output: data/gene_coords/ENSSSCG00000023666.gene, data/var_coords/ENSSSCG00000023666.vars

RuleException:
CalledProcessError in line 18 of /home/pelmo/tesi/remap_sscrofa/Snakefile:
Command 'set -euo pipefail;  /home/pelmo/anaconda3/envs/snakemake/bin/python3.9 /home/pelmo/tesi/remap_sscrofa/.snakemake/scripts/tmpnhgztbd6.get_coords.py' returned non-zero exit status 1.
  File "/home/pelmo/anaconda3/envs/snakemake/lib/python3.9/site-packages/snakemake/executors/__init__.py", line 2231, in run_wrapper
  File "/home/pelmo/tesi/remap_sscrofa/Snakefile", line 18, in __rule_get_coords
  File "/home/pelmo/anaconda3/envs/snakemake/lib/python3.9/site-packages/snakemake/executors/__init__.py", line 560, in _callback
  File "/home/pelmo/anaconda3/envs/snakemake/lib/python3.9/concurrent/futures/thread.py", line 52, in run
  File "/home/pelmo/anaconda3/envs/snakemake/lib/python3.9/site-packages/snakemake/executors/__init__.py", line 546, in cached_or_run
  File "/home/pelmo/anaconda3/envs/snakemake/lib/python3.9/site-packages/snakemake/executors/__init__.py", line 2262, in run_wrapper
[Thu Nov 19 09:25:29 2020]
Error in rule get_coords:
    jobid: 116
    output: data/gene_coords/ENSSSCG00000007218.gene, data/var_coords/ENSSSCG00000007218.vars

RuleException:
CalledProcessError in line 18 of /home/pelmo/tesi/remap_sscrofa/Snakefile:
Command 'set -euo pipefail;  /home/pelmo/anaconda3/envs/snakemake/bin/python3.9 /home/pelmo/tesi/remap_sscrofa/.snakemake/scripts/tmpax78wgx6.get_coords.py' returned non-zero exit status 1.
  File "/home/pelmo/anaconda3/envs/snakemake/lib/python3.9/site-packages/snakemake/executors/__init__.py", line 2231, in run_wrapper
  File "/home/pelmo/tesi/remap_sscrofa/Snakefile", line 18, in __rule_get_coords
  File "/home/pelmo/anaconda3/envs/snakemake/lib/python3.9/site-packages/snakemake/executors/__init__.py", line 560, in _callback
  File "/home/pelmo/anaconda3/envs/snakemake/lib/python3.9/concurrent/futures/thread.py", line 52, in run
  File "/home/pelmo/anaconda3/envs/snakemake/lib/python3.9/site-packages/snakemake/executors/__init__.py", line 546, in cached_or_run
  File "/home/pelmo/anaconda3/envs/snakemake/lib/python3.9/site-packages/snakemake/executors/__init__.py", line 2262, in run_wrapper
[Thu Nov 19 09:25:29 2020]
Error in rule get_coords:
    jobid: 56
    output: data/gene_coords/ENSSSCG00000020924.gene, data/var_coords/ENSSSCG00000020924.vars

RuleException:
CalledProcessError in line 18 of /home/pelmo/tesi/remap_sscrofa/Snakefile:
Command 'set -euo pipefail;  /home/pelmo/anaconda3/envs/snakemake/bin/python3.9 /home/pelmo/tesi/remap_sscrofa/.snakemake/scripts/tmp7uixxatx.get_coords.py' returned non-zero exit status 1.
  File "/home/pelmo/anaconda3/envs/snakemake/lib/python3.9/site-packages/snakemake/executors/__init__.py", line 2231, in run_wrapper
  File "/home/pelmo/tesi/remap_sscrofa/Snakefile", line 18, in __rule_get_coords
  File "/home/pelmo/anaconda3/envs/snakemake/lib/python3.9/site-packages/snakemake/executors/__init__.py", line 560, in _callback
  File "/home/pelmo/anaconda3/envs/snakemake/lib/python3.9/concurrent/futures/thread.py", line 52, in run
  File "/home/pelmo/anaconda3/envs/snakemake/lib/python3.9/site-packages/snakemake/executors/__init__.py", line 546, in cached_or_run
  File "/home/pelmo/anaconda3/envs/snakemake/lib/python3.9/site-packages/snakemake/executors/__init__.py", line 2262, in run_wrapper
[Thu Nov 19 09:25:29 2020]
Error in rule get_coords:
    jobid: 11
    output: data/gene_coords/ENSSSCG00000031002.gene, data/var_coords/ENSSSCG00000031002.vars

RuleException:
CalledProcessError in line 18 of /home/pelmo/tesi/remap_sscrofa/Snakefile:
Command 'set -euo pipefail;  /home/pelmo/anaconda3/envs/snakemake/bin/python3.9 /home/pelmo/tesi/remap_sscrofa/.snakemake/scripts/tmpildykfj6.get_coords.py' returned non-zero exit status 1.
  File "/home/pelmo/anaconda3/envs/snakemake/lib/python3.9/site-packages/snakemake/executors/__init__.py", line 2231, in run_wrapper
  File "/home/pelmo/tesi/remap_sscrofa/Snakefile", line 18, in __rule_get_coords
  File "/home/pelmo/anaconda3/envs/snakemake/lib/python3.9/site-packages/snakemake/executors/__init__.py", line 560, in _callback
  File "/home/pelmo/anaconda3/envs/snakemake/lib/python3.9/concurrent/futures/thread.py", line 52, in run
  File "/home/pelmo/anaconda3/envs/snakemake/lib/python3.9/site-packages/snakemake/executors/__init__.py", line 546, in cached_or_run
  File "/home/pelmo/anaconda3/envs/snakemake/lib/python3.9/site-packages/snakemake/executors/__init__.py", line 2262, in run_wrapper
[Thu Nov 19 09:25:29 2020]
Error in rule get_coords:
    jobid: 27
[Thu Nov 19 09:25:29 2020]
    output: data/gene_coords/ENSSSCG00000014428.gene, data/var_coords/ENSSSCG00000014428.vars
Error in rule get_coords:

    jobid: 41
    output: data/gene_coords/ENSSSCG00000011436.gene, data/var_coords/ENSSSCG00000011436.vars

RuleException:
CalledProcessError in line 18 of /home/pelmo/tesi/remap_sscrofa/Snakefile:
Command 'set -euo pipefail;  /home/pelmo/anaconda3/envs/snakemake/bin/python3.9 /home/pelmo/tesi/remap_sscrofa/.snakemake/scripts/tmpc4_4zyp5.get_coords.py' returned non-zero exit status 1.
  File "/home/pelmo/anaconda3/envs/snakemake/lib/python3.9/site-packages/snakemake/executors/__init__.py", line 2231, in run_wrapper
  File "/home/pelmo/tesi/remap_sscrofa/Snakefile", line 18, in __rule_get_coords
  File "/home/pelmo/anaconda3/envs/snakemake/lib/python3.9/site-packages/snakemake/executors/__init__.py", line 560, in _callback
  File "/home/pelmo/anaconda3/envs/snakemake/lib/python3.9/concurrent/futures/thread.py", line 52, in run
  File "/home/pelmo/anaconda3/envs/snakemake/lib/python3.9/site-packages/snakemake/executors/__init__.py", line 546, in cached_or_run
  File "/home/pelmo/anaconda3/envs/snakemake/lib/python3.9/site-packages/snakemake/executors/__init__.py", line 2262, in run_wrapper
RuleException:
CalledProcessError in line 18 of /home/pelmo/tesi/remap_sscrofa/Snakefile:
Command 'set -euo pipefail;  /home/pelmo/anaconda3/envs/snakemake/bin/python3.9 /home/pelmo/tesi/remap_sscrofa/.snakemake/scripts/tmpf26xez41.get_coords.py' returned non-zero exit status 1.
  File "/home/pelmo/anaconda3/envs/snakemake/lib/python3.9/site-packages/snakemake/executors/__init__.py", line 2231, in run_wrapper
  File "/home/pelmo/tesi/remap_sscrofa/Snakefile", line 18, in __rule_get_coords
  File "/home/pelmo/anaconda3/envs/snakemake/lib/python3.9/site-packages/snakemake/executors/__init__.py", line 560, in _callback
  File "/home/pelmo/anaconda3/envs/snakemake/lib/python3.9/concurrent/futures/thread.py", line 52, in run
  File "/home/pelmo/anaconda3/envs/snakemake/lib/python3.9/site-packages/snakemake/executors/__init__.py", line 546, in cached_or_run
  File "/home/pelmo/anaconda3/envs/snakemake/lib/python3.9/site-packages/snakemake/executors/__init__.py", line 2262, in run_wrapper
[Thu Nov 19 09:25:29 2020]
Error in rule get_coords:
    jobid: 86
    output: data/gene_coords/ENSSSCG00000002756.gene, data/var_coords/ENSSSCG00000002756.vars

RuleException:
CalledProcessError in line 18 of /home/pelmo/tesi/remap_sscrofa/Snakefile:
Command 'set -euo pipefail;  /home/pelmo/anaconda3/envs/snakemake/bin/python3.9 /home/pelmo/tesi/remap_sscrofa/.snakemake/scripts/tmpy_7_i100.get_coords.py' returned non-zero exit status 1.
  File "/home/pelmo/anaconda3/envs/snakemake/lib/python3.9/site-packages/snakemake/executors/__init__.py", line 2231, in run_wrapper
  File "/home/pelmo/tesi/remap_sscrofa/Snakefile", line 18, in __rule_get_coords
  File "/home/pelmo/anaconda3/envs/snakemake/lib/python3.9/site-packages/snakemake/executors/__init__.py", line 560, in _callback
  File "/home/pelmo/anaconda3/envs/snakemake/lib/python3.9/concurrent/futures/thread.py", line 52, in run
  File "/home/pelmo/anaconda3/envs/snakemake/lib/python3.9/site-packages/snakemake/executors/__init__.py", line 546, in cached_or_run
  File "/home/pelmo/anaconda3/envs/snakemake/lib/python3.9/site-packages/snakemake/executors/__init__.py", line 2262, in run_wrapper
Shutting down, this might take some time.
Exiting because a job execution failed. Look above for error message
Complete log: /home/pelmo/tesi/remap_sscrofa/.snakemake/log/2020-11-19T092527.914107.snakemake.log
