Building DAG of jobs...
Using shell: /usr/bin/bash
Provided cores: 7
Rules claiming more threads will be scaled down.
Job counts:
	count	jobs
	1	all
	134	get_ncbi
	135

[Thu Nov 19 17:35:23 2020]
rule get_ncbi:
    input: data/complete_coords/ENSSSCG00000010885.complete
    output: data/ncbi_coords/ENSSSCG00000010885.ncbi
    jobid: 245
    wildcards: id=ENSSSCG00000010885

[Thu Nov 19 17:35:23 2020]
rule get_ncbi:
    input: data/complete_coords/ENSSSCG00000001050.complete
    output: data/ncbi_coords/ENSSSCG00000001050.ncbi
    jobid: 67
    wildcards: id=ENSSSCG00000001050

[Thu Nov 19 17:35:23 2020]
rule get_ncbi:
    input: data/complete_coords/ENSSSCG00000031002.complete
    output: data/ncbi_coords/ENSSSCG00000031002.ncbi
    jobid: 21
    wildcards: id=ENSSSCG00000031002

[Thu Nov 19 17:35:23 2020]
rule get_ncbi:
    input: data/complete_coords/ENSSSCG00000026201.complete
    output: data/ncbi_coords/ENSSSCG00000026201.ncbi
    jobid: 41
    wildcards: id=ENSSSCG00000026201

[Thu Nov 19 17:35:23 2020]
rule get_ncbi:
    input: data/complete_coords/ENSSSCG00000023666.complete
    output: data/ncbi_coords/ENSSSCG00000023666.ncbi
    jobid: 51
    wildcards: id=ENSSSCG00000023666

[Thu Nov 19 17:35:23 2020]
rule get_ncbi:
    input: data/complete_coords/ENSSSCG00000007218.complete
    output: data/ncbi_coords/ENSSSCG00000007218.ncbi
    jobid: 231
    wildcards: id=ENSSSCG00000007218

[Thu Nov 19 17:35:23 2020]
rule get_ncbi:
    input: data/complete_coords/ENSSSCG00000005193.complete
    output: data/ncbi_coords/ENSSSCG00000005193.ncbi
    jobid: 141
    wildcards: id=ENSSSCG00000005193

[Thu Nov 19 17:35:24 2020]
Error in rule get_ncbi:
    jobid: 67
    output: data/ncbi_coords/ENSSSCG00000001050.ncbi

RuleException:
CalledProcessError in line 28 of /home/pelmo/tesi/remap_sscrofa/Snakefile:
Command 'set -euo pipefail;  /home/pelmo/anaconda3/envs/snakemake/bin/python3.9 /home/pelmo/tesi/remap_sscrofa/.snakemake/scripts/tmp3hkwv_xx.get_ncbi.py' returned non-zero exit status 1.
  File "/home/pelmo/anaconda3/envs/snakemake/lib/python3.9/site-packages/snakemake/executors/__init__.py", line 2231, in run_wrapper
  File "/home/pelmo/tesi/remap_sscrofa/Snakefile", line 28, in __rule_get_ncbi
  File "/home/pelmo/anaconda3/envs/snakemake/lib/python3.9/site-packages/snakemake/executors/__init__.py", line 560, in _callback
  File "/home/pelmo/anaconda3/envs/snakemake/lib/python3.9/concurrent/futures/thread.py", line 52, in run
  File "/home/pelmo/anaconda3/envs/snakemake/lib/python3.9/site-packages/snakemake/executors/__init__.py", line 546, in cached_or_run
  File "/home/pelmo/anaconda3/envs/snakemake/lib/python3.9/site-packages/snakemake/executors/__init__.py", line 2262, in run_wrapper
[Thu Nov 19 17:35:24 2020]
Error in rule get_ncbi:
    jobid: 41
    output: data/ncbi_coords/ENSSSCG00000026201.ncbi

RuleException:
CalledProcessError in line 28 of /home/pelmo/tesi/remap_sscrofa/Snakefile:
Command 'set -euo pipefail;  /home/pelmo/anaconda3/envs/snakemake/bin/python3.9 /home/pelmo/tesi/remap_sscrofa/.snakemake/scripts/tmp7yk3ni2r.get_ncbi.py' returned non-zero exit status 1.
  File "/home/pelmo/anaconda3/envs/snakemake/lib/python3.9/site-packages/snakemake/executors/__init__.py", line 2231, in run_wrapper
  File "/home/pelmo/tesi/remap_sscrofa/Snakefile", line 28, in __rule_get_ncbi
  File "/home/pelmo/anaconda3/envs/snakemake/lib/python3.9/site-packages/snakemake/executors/__init__.py", line 560, in _callback
  File "/home/pelmo/anaconda3/envs/snakemake/lib/python3.9/concurrent/futures/thread.py", line 52, in run
  File "/home/pelmo/anaconda3/envs/snakemake/lib/python3.9/site-packages/snakemake/executors/__init__.py", line 546, in cached_or_run
  File "/home/pelmo/anaconda3/envs/snakemake/lib/python3.9/site-packages/snakemake/executors/__init__.py", line 2262, in run_wrapper
[Thu Nov 19 17:35:24 2020]
Error in rule get_ncbi:
    jobid: 141
    output: data/ncbi_coords/ENSSSCG00000005193.ncbi

RuleException:
CalledProcessError in line 28 of /home/pelmo/tesi/remap_sscrofa/Snakefile:
Command 'set -euo pipefail;  /home/pelmo/anaconda3/envs/snakemake/bin/python3.9 /home/pelmo/tesi/remap_sscrofa/.snakemake/scripts/tmpm7jvwciu.get_ncbi.py' returned non-zero exit status 1.
  File "/home/pelmo/anaconda3/envs/snakemake/lib/python3.9/site-packages/snakemake/executors/__init__.py", line 2231, in run_wrapper
  File "/home/pelmo/tesi/remap_sscrofa/Snakefile", line 28, in __rule_get_ncbi
  File "/home/pelmo/anaconda3/envs/snakemake/lib/python3.9/site-packages/snakemake/executors/__init__.py", line 560, in _callback
  File "/home/pelmo/anaconda3/envs/snakemake/lib/python3.9/concurrent/futures/thread.py", line 52, in run
  File "/home/pelmo/anaconda3/envs/snakemake/lib/python3.9/site-packages/snakemake/executors/__init__.py", line 546, in cached_or_run
  File "/home/pelmo/anaconda3/envs/snakemake/lib/python3.9/site-packages/snakemake/executors/__init__.py", line 2262, in run_wrapper
[Thu Nov 19 17:35:24 2020]
Error in rule get_ncbi:
    jobid: 245
    output: data/ncbi_coords/ENSSSCG00000010885.ncbi

RuleException:
CalledProcessError in line 28 of /home/pelmo/tesi/remap_sscrofa/Snakefile:
Command 'set -euo pipefail;  /home/pelmo/anaconda3/envs/snakemake/bin/python3.9 /home/pelmo/tesi/remap_sscrofa/.snakemake/scripts/tmp3ewjtxn8.get_ncbi.py' returned non-zero exit status 1.
  File "/home/pelmo/anaconda3/envs/snakemake/lib/python3.9/site-packages/snakemake/executors/__init__.py", line 2231, in run_wrapper
  File "/home/pelmo/tesi/remap_sscrofa/Snakefile", line 28, in __rule_get_ncbi
  File "/home/pelmo/anaconda3/envs/snakemake/lib/python3.9/site-packages/snakemake/executors/__init__.py", line 560, in _callback
  File "/home/pelmo/anaconda3/envs/snakemake/lib/python3.9/concurrent/futures/thread.py", line 52, in run
  File "/home/pelmo/anaconda3/envs/snakemake/lib/python3.9/site-packages/snakemake/executors/__init__.py", line 546, in cached_or_run
  File "/home/pelmo/anaconda3/envs/snakemake/lib/python3.9/site-packages/snakemake/executors/__init__.py", line 2262, in run_wrapper
[Thu Nov 19 17:35:24 2020]
Error in rule get_ncbi:
    jobid: 231
    output: data/ncbi_coords/ENSSSCG00000007218.ncbi

RuleException:
CalledProcessError in line 28 of /home/pelmo/tesi/remap_sscrofa/Snakefile:
Command 'set -euo pipefail;  /home/pelmo/anaconda3/envs/snakemake/bin/python3.9 /home/pelmo/tesi/remap_sscrofa/.snakemake/scripts/tmpy_i2olh0.get_ncbi.py' returned non-zero exit status 1.
  File "/home/pelmo/anaconda3/envs/snakemake/lib/python3.9/site-packages/snakemake/executors/__init__.py", line 2231, in run_wrapper
  File "/home/pelmo/tesi/remap_sscrofa/Snakefile", line 28, in __rule_get_ncbi
  File "/home/pelmo/anaconda3/envs/snakemake/lib/python3.9/site-packages/snakemake/executors/__init__.py", line 560, in _callback
  File "/home/pelmo/anaconda3/envs/snakemake/lib/python3.9/concurrent/futures/thread.py", line 52, in run
  File "/home/pelmo/anaconda3/envs/snakemake/lib/python3.9/site-packages/snakemake/executors/__init__.py", line 546, in cached_or_run
  File "/home/pelmo/anaconda3/envs/snakemake/lib/python3.9/site-packages/snakemake/executors/__init__.py", line 2262, in run_wrapper
[Thu Nov 19 17:35:24 2020]
Error in rule get_ncbi:
    jobid: 21
    output: data/ncbi_coords/ENSSSCG00000031002.ncbi

RuleException:
CalledProcessError in line 28 of /home/pelmo/tesi/remap_sscrofa/Snakefile:
Command 'set -euo pipefail;  /home/pelmo/anaconda3/envs/snakemake/bin/python3.9 /home/pelmo/tesi/remap_sscrofa/.snakemake/scripts/tmp95590hcp.get_ncbi.py' returned non-zero exit status 1.
  File "/home/pelmo/anaconda3/envs/snakemake/lib/python3.9/site-packages/snakemake/executors/__init__.py", line 2231, in run_wrapper
  File "/home/pelmo/tesi/remap_sscrofa/Snakefile", line 28, in __rule_get_ncbi
  File "/home/pelmo/anaconda3/envs/snakemake/lib/python3.9/site-packages/snakemake/executors/__init__.py", line 560, in _callback
  File "/home/pelmo/anaconda3/envs/snakemake/lib/python3.9/concurrent/futures/thread.py", line 52, in run
  File "/home/pelmo/anaconda3/envs/snakemake/lib/python3.9/site-packages/snakemake/executors/__init__.py", line 546, in cached_or_run
  File "/home/pelmo/anaconda3/envs/snakemake/lib/python3.9/site-packages/snakemake/executors/__init__.py", line 2262, in run_wrapper
[Thu Nov 19 17:35:24 2020]
Error in rule get_ncbi:
    jobid: 51
    output: data/ncbi_coords/ENSSSCG00000023666.ncbi

RuleException:
CalledProcessError in line 28 of /home/pelmo/tesi/remap_sscrofa/Snakefile:
Command 'set -euo pipefail;  /home/pelmo/anaconda3/envs/snakemake/bin/python3.9 /home/pelmo/tesi/remap_sscrofa/.snakemake/scripts/tmpuq8xmdwr.get_ncbi.py' returned non-zero exit status 1.
  File "/home/pelmo/anaconda3/envs/snakemake/lib/python3.9/site-packages/snakemake/executors/__init__.py", line 2231, in run_wrapper
  File "/home/pelmo/tesi/remap_sscrofa/Snakefile", line 28, in __rule_get_ncbi
  File "/home/pelmo/anaconda3/envs/snakemake/lib/python3.9/site-packages/snakemake/executors/__init__.py", line 560, in _callback
  File "/home/pelmo/anaconda3/envs/snakemake/lib/python3.9/concurrent/futures/thread.py", line 52, in run
  File "/home/pelmo/anaconda3/envs/snakemake/lib/python3.9/site-packages/snakemake/executors/__init__.py", line 546, in cached_or_run
  File "/home/pelmo/anaconda3/envs/snakemake/lib/python3.9/site-packages/snakemake/executors/__init__.py", line 2262, in run_wrapper
Shutting down, this might take some time.
Exiting because a job execution failed. Look above for error message
Complete log: /home/pelmo/tesi/remap_sscrofa/.snakemake/log/2020-11-19T173523.314696.snakemake.log
