Building DAG of jobs...
Using shell: /usr/bin/bash
Provided cores: 7
Rules claiming more threads will be scaled down.
Job counts:
	count	jobs
	1	all
	134	verify_vars
	135
Select jobs to execute...

[Tue Dec  1 15:38:17 2020]
rule verify_vars:
    input: data/remapped_vars/ENSSSCG00000003017.remapped
    output: data/verified_vars/ENSSSCG00000003017.verified
    jobid: 392
    wildcards: id=ENSSSCG00000003017

[Tue Dec  1 15:38:17 2020]
rule verify_vars:
    input: data/remapped_vars/ENSSSCG00000010948.remapped
    output: data/verified_vars/ENSSSCG00000010948.verified
    jobid: 321
    wildcards: id=ENSSSCG00000010948

[Tue Dec  1 15:38:17 2020]
rule verify_vars:
    input: data/remapped_vars/ENSSSCG00000010459.remapped
    output: data/verified_vars/ENSSSCG00000010459.verified
    jobid: 320
    wildcards: id=ENSSSCG00000010459

[Tue Dec  1 15:38:17 2020]
rule verify_vars:
    input: data/remapped_vars/ENSSSCG00000008326.remapped
    output: data/verified_vars/ENSSSCG00000008326.verified
    jobid: 269
    wildcards: id=ENSSSCG00000008326

[Tue Dec  1 15:38:17 2020]
rule verify_vars:
    input: data/remapped_vars/ENSSSCG00000002749.remapped
    output: data/verified_vars/ENSSSCG00000002749.verified
    jobid: 277
    wildcards: id=ENSSSCG00000002749

[Tue Dec  1 15:38:17 2020]
rule verify_vars:
    input: data/remapped_vars/ENSSSCG00000008842.remapped
    output: data/verified_vars/ENSSSCG00000008842.verified
    jobid: 292
    wildcards: id=ENSSSCG00000008842

[Tue Dec  1 15:38:17 2020]
rule verify_vars:
    input: data/remapped_vars/ENSSSCG00000027877.remapped
    output: data/verified_vars/ENSSSCG00000027877.verified
    jobid: 350
    wildcards: id=ENSSSCG00000027877

[Tue Dec  1 15:38:19 2020]
[Tue Dec  1 15:38:19 2020]
Error in rule verify_vars:
Error in rule verify_vars:
    jobid: 277
    jobid: 350
    output: data/verified_vars/ENSSSCG00000002749.verified
    output: data/verified_vars/ENSSSCG00000027877.verified


RuleException:
CalledProcessError in line 41 of /home/pelmo/sscrofa_variant_remapping/Snakefile:
Command 'set -euo pipefail;  /home/pelmo/anaconda3/envs/snakemake/bin/python3.9 /home/pelmo/sscrofa_variant_remapping/.snakemake/scripts/tmpbn2w9ygq.var_confirmation.py' returned non-zero exit status 1.
  File "/home/pelmo/anaconda3/envs/snakemake/lib/python3.9/site-packages/snakemake/executors/__init__.py", line 2273, in run_wrapper
  File "/home/pelmo/sscrofa_variant_remapping/Snakefile", line 41, in __rule_verify_vars
  File "/home/pelmo/anaconda3/envs/snakemake/lib/python3.9/site-packages/snakemake/executors/__init__.py", line 560, in _callback
  File "/home/pelmo/anaconda3/envs/snakemake/lib/python3.9/concurrent/futures/thread.py", line 52, in run
  File "/home/pelmo/anaconda3/envs/snakemake/lib/python3.9/site-packages/snakemake/executors/__init__.py", line 546, in cached_or_run
  File "/home/pelmo/anaconda3/envs/snakemake/lib/python3.9/site-packages/snakemake/executors/__init__.py", line 2304, in run_wrapper
RuleException:
CalledProcessError in line 41 of /home/pelmo/sscrofa_variant_remapping/Snakefile:
Command 'set -euo pipefail;  /home/pelmo/anaconda3/envs/snakemake/bin/python3.9 /home/pelmo/sscrofa_variant_remapping/.snakemake/scripts/tmpwxvyex08.var_confirmation.py' returned non-zero exit status 1.
  File "/home/pelmo/anaconda3/envs/snakemake/lib/python3.9/site-packages/snakemake/executors/__init__.py", line 2273, in run_wrapper
  File "/home/pelmo/sscrofa_variant_remapping/Snakefile", line 41, in __rule_verify_vars
  File "/home/pelmo/anaconda3/envs/snakemake/lib/python3.9/site-packages/snakemake/executors/__init__.py", line 560, in _callback
  File "/home/pelmo/anaconda3/envs/snakemake/lib/python3.9/concurrent/futures/thread.py", line 52, in run
  File "/home/pelmo/anaconda3/envs/snakemake/lib/python3.9/site-packages/snakemake/executors/__init__.py", line 546, in cached_or_run
  File "/home/pelmo/anaconda3/envs/snakemake/lib/python3.9/site-packages/snakemake/executors/__init__.py", line 2304, in run_wrapper
[Tue Dec  1 15:38:19 2020]
Error in rule verify_vars:
    jobid: 320
    output: data/verified_vars/ENSSSCG00000010459.verified

[Tue Dec  1 15:38:19 2020]
Error in rule verify_vars:
    jobid: 321
    output: data/verified_vars/ENSSSCG00000010948.verified
RuleException:
CalledProcessError in line 41 of /home/pelmo/sscrofa_variant_remapping/Snakefile:
Command 'set -euo pipefail;  /home/pelmo/anaconda3/envs/snakemake/bin/python3.9 /home/pelmo/sscrofa_variant_remapping/.snakemake/scripts/tmpxvp40y03.var_confirmation.py' returned non-zero exit status 1.
  File "/home/pelmo/anaconda3/envs/snakemake/lib/python3.9/site-packages/snakemake/executors/__init__.py", line 2273, in run_wrapper
  File "/home/pelmo/sscrofa_variant_remapping/Snakefile", line 41, in __rule_verify_vars
  File "/home/pelmo/anaconda3/envs/snakemake/lib/python3.9/site-packages/snakemake/executors/__init__.py", line 560, in _callback
  File "/home/pelmo/anaconda3/envs/snakemake/lib/python3.9/concurrent/futures/thread.py", line 52, in run
  File "/home/pelmo/anaconda3/envs/snakemake/lib/python3.9/site-packages/snakemake/executors/__init__.py", line 546, in cached_or_run
  File "/home/pelmo/anaconda3/envs/snakemake/lib/python3.9/site-packages/snakemake/executors/__init__.py", line 2304, in run_wrapper

RuleException:
CalledProcessError in line 41 of /home/pelmo/sscrofa_variant_remapping/Snakefile:
Command 'set -euo pipefail;  /home/pelmo/anaconda3/envs/snakemake/bin/python3.9 /home/pelmo/sscrofa_variant_remapping/.snakemake/scripts/tmp2mk119ix.var_confirmation.py' returned non-zero exit status 1.
  File "/home/pelmo/anaconda3/envs/snakemake/lib/python3.9/site-packages/snakemake/executors/__init__.py", line 2273, in run_wrapper
  File "/home/pelmo/sscrofa_variant_remapping/Snakefile", line 41, in __rule_verify_vars
  File "/home/pelmo/anaconda3/envs/snakemake/lib/python3.9/site-packages/snakemake/executors/__init__.py", line 560, in _callback
  File "/home/pelmo/anaconda3/envs/snakemake/lib/python3.9/concurrent/futures/thread.py", line 52, in run
  File "/home/pelmo/anaconda3/envs/snakemake/lib/python3.9/site-packages/snakemake/executors/__init__.py", line 546, in cached_or_run
  File "/home/pelmo/anaconda3/envs/snakemake/lib/python3.9/site-packages/snakemake/executors/__init__.py", line 2304, in run_wrapper
[Tue Dec  1 15:38:19 2020]
Error in rule verify_vars:
    jobid: 392
    output: data/verified_vars/ENSSSCG00000003017.verified

RuleException:
CalledProcessError in line 41 of /home/pelmo/sscrofa_variant_remapping/Snakefile:
Command 'set -euo pipefail;  /home/pelmo/anaconda3/envs/snakemake/bin/python3.9 /home/pelmo/sscrofa_variant_remapping/.snakemake/scripts/tmpmy1kac_n.var_confirmation.py' returned non-zero exit status 1.
  File "/home/pelmo/anaconda3/envs/snakemake/lib/python3.9/site-packages/snakemake/executors/__init__.py", line 2273, in run_wrapper
  File "/home/pelmo/sscrofa_variant_remapping/Snakefile", line 41, in __rule_verify_vars
  File "/home/pelmo/anaconda3/envs/snakemake/lib/python3.9/site-packages/snakemake/executors/__init__.py", line 560, in _callback
  File "/home/pelmo/anaconda3/envs/snakemake/lib/python3.9/concurrent/futures/thread.py", line 52, in run
  File "/home/pelmo/anaconda3/envs/snakemake/lib/python3.9/site-packages/snakemake/executors/__init__.py", line 546, in cached_or_run
  File "/home/pelmo/anaconda3/envs/snakemake/lib/python3.9/site-packages/snakemake/executors/__init__.py", line 2304, in run_wrapper
[Tue Dec  1 15:38:19 2020]
Error in rule verify_vars:
    jobid: 292
    output: data/verified_vars/ENSSSCG00000008842.verified

RuleException:
CalledProcessError in line 41 of /home/pelmo/sscrofa_variant_remapping/Snakefile:
Command 'set -euo pipefail;  /home/pelmo/anaconda3/envs/snakemake/bin/python3.9 /home/pelmo/sscrofa_variant_remapping/.snakemake/scripts/tmplwff5dt2.var_confirmation.py' returned non-zero exit status 1.
  File "/home/pelmo/anaconda3/envs/snakemake/lib/python3.9/site-packages/snakemake/executors/__init__.py", line 2273, in run_wrapper
  File "/home/pelmo/sscrofa_variant_remapping/Snakefile", line 41, in __rule_verify_vars
  File "/home/pelmo/anaconda3/envs/snakemake/lib/python3.9/site-packages/snakemake/executors/__init__.py", line 560, in _callback
  File "/home/pelmo/anaconda3/envs/snakemake/lib/python3.9/concurrent/futures/thread.py", line 52, in run
  File "/home/pelmo/anaconda3/envs/snakemake/lib/python3.9/site-packages/snakemake/executors/__init__.py", line 546, in cached_or_run
  File "/home/pelmo/anaconda3/envs/snakemake/lib/python3.9/site-packages/snakemake/executors/__init__.py", line 2304, in run_wrapper
[Tue Dec  1 15:38:19 2020]
Error in rule verify_vars:
    jobid: 269
    output: data/verified_vars/ENSSSCG00000008326.verified

RuleException:
CalledProcessError in line 41 of /home/pelmo/sscrofa_variant_remapping/Snakefile:
Command 'set -euo pipefail;  /home/pelmo/anaconda3/envs/snakemake/bin/python3.9 /home/pelmo/sscrofa_variant_remapping/.snakemake/scripts/tmp9e86_1en.var_confirmation.py' returned non-zero exit status 1.
  File "/home/pelmo/anaconda3/envs/snakemake/lib/python3.9/site-packages/snakemake/executors/__init__.py", line 2273, in run_wrapper
  File "/home/pelmo/sscrofa_variant_remapping/Snakefile", line 41, in __rule_verify_vars
  File "/home/pelmo/anaconda3/envs/snakemake/lib/python3.9/site-packages/snakemake/executors/__init__.py", line 560, in _callback
  File "/home/pelmo/anaconda3/envs/snakemake/lib/python3.9/concurrent/futures/thread.py", line 52, in run
  File "/home/pelmo/anaconda3/envs/snakemake/lib/python3.9/site-packages/snakemake/executors/__init__.py", line 546, in cached_or_run
  File "/home/pelmo/anaconda3/envs/snakemake/lib/python3.9/site-packages/snakemake/executors/__init__.py", line 2304, in run_wrapper
Shutting down, this might take some time.
Exiting because a job execution failed. Look above for error message
Complete log: /home/pelmo/sscrofa_variant_remapping/.snakemake/log/2020-12-01T153816.993953.snakemake.log
