Building DAG of jobs...
Using shell: /usr/bin/bash
Provided cores: 7
Rules claiming more threads will be scaled down.
Job counts:
	count	jobs
	1	all
	134	merge_results
	135
Select jobs to execute...

[Mon Nov 23 15:04:20 2020]
rule merge_results:
    input: data/var_coords_remapped_report/ENSSSCG00000001404.vars.report, data/complete_coords/ENSSSCG00000001404.complete
    output: data/remapped_vars/ENSSSCG00000001404.remapped, data/unmapped_vars/ENSSSCG00000001404.unmapped
    jobid: 87
    wildcards: id=ENSSSCG00000001404

[Mon Nov 23 15:04:20 2020]
rule merge_results:
    input: data/var_coords_remapped_report/ENSSSCG00000012840.vars.report, data/complete_coords/ENSSSCG00000012840.complete
    output: data/remapped_vars/ENSSSCG00000012840.remapped, data/unmapped_vars/ENSSSCG00000012840.unmapped
    jobid: 177
    wildcards: id=ENSSSCG00000012840

[Mon Nov 23 15:04:20 2020]
rule merge_results:
    input: data/var_coords_remapped_report/ENSSSCG00000007217.vars.report, data/complete_coords/ENSSSCG00000007217.complete
    output: data/remapped_vars/ENSSSCG00000007217.remapped, data/unmapped_vars/ENSSSCG00000007217.unmapped
    jobid: 117
    wildcards: id=ENSSSCG00000007217

[Mon Nov 23 15:04:20 2020]
rule merge_results:
    input: data/var_coords_remapped_report/ENSSSCG00000006924.vars.report, data/complete_coords/ENSSSCG00000006924.complete
    output: data/remapped_vars/ENSSSCG00000006924.remapped, data/unmapped_vars/ENSSSCG00000006924.unmapped
    jobid: 267
    wildcards: id=ENSSSCG00000006924

[Mon Nov 23 15:04:20 2020]
rule merge_results:
    input: data/var_coords_remapped_report/ENSSSCG00000027555.vars.report, data/complete_coords/ENSSSCG00000027555.complete
    output: data/remapped_vars/ENSSSCG00000027555.remapped, data/unmapped_vars/ENSSSCG00000027555.unmapped
    jobid: 193
    wildcards: id=ENSSSCG00000027555

[Mon Nov 23 15:04:20 2020]
rule merge_results:
    input: data/var_coords_remapped_report/ENSSSCG00000000038.vars.report, data/complete_coords/ENSSSCG00000000038.complete
    output: data/remapped_vars/ENSSSCG00000000038.remapped, data/unmapped_vars/ENSSSCG00000000038.unmapped
    jobid: 251
    wildcards: id=ENSSSCG00000000038

[Mon Nov 23 15:04:20 2020]
rule merge_results:
    input: data/var_coords_remapped_report/ENSSSCG00000028629.vars.report, data/complete_coords/ENSSSCG00000028629.complete
    output: data/remapped_vars/ENSSSCG00000028629.remapped, data/unmapped_vars/ENSSSCG00000028629.unmapped
    jobid: 179
    wildcards: id=ENSSSCG00000028629

[Mon Nov 23 15:04:20 2020]
Error in rule merge_results:
    jobid: 177
    output: data/remapped_vars/ENSSSCG00000012840.remapped, data/unmapped_vars/ENSSSCG00000012840.unmapped

RuleException:
CalledProcessError in line 30 of /home/pelmo/sscrofa_variant_remapping/Snakefile:
Command 'set -euo pipefail;  /home/pelmo/anaconda3/envs/snakemake/bin/python3.9 /home/pelmo/sscrofa_variant_remapping/.snakemake/scripts/tmpmgx3dzp6.merge_results.py' returned non-zero exit status 1.
  File "/home/pelmo/anaconda3/envs/snakemake/lib/python3.9/site-packages/snakemake/executors/__init__.py", line 2273, in run_wrapper
  File "/home/pelmo/sscrofa_variant_remapping/Snakefile", line 30, in __rule_merge_results
  File "/home/pelmo/anaconda3/envs/snakemake/lib/python3.9/site-packages/snakemake/executors/__init__.py", line 560, in _callback
  File "/home/pelmo/anaconda3/envs/snakemake/lib/python3.9/concurrent/futures/thread.py", line 52, in run
  File "/home/pelmo/anaconda3/envs/snakemake/lib/python3.9/site-packages/snakemake/executors/__init__.py", line 546, in cached_or_run
  File "/home/pelmo/anaconda3/envs/snakemake/lib/python3.9/site-packages/snakemake/executors/__init__.py", line 2304, in run_wrapper
[Mon Nov 23 15:04:20 2020]
Error in rule merge_results:
    jobid: 251
    output: data/remapped_vars/ENSSSCG00000000038.remapped, data/unmapped_vars/ENSSSCG00000000038.unmapped

RuleException:
CalledProcessError in line 30 of /home/pelmo/sscrofa_variant_remapping/Snakefile:
Command 'set -euo pipefail;  /home/pelmo/anaconda3/envs/snakemake/bin/python3.9 /home/pelmo/sscrofa_variant_remapping/.snakemake/scripts/tmpb17rwm9h.merge_results.py' returned non-zero exit status 1.
  File "/home/pelmo/anaconda3/envs/snakemake/lib/python3.9/site-packages/snakemake/executors/__init__.py", line 2273, in run_wrapper
  File "/home/pelmo/sscrofa_variant_remapping/Snakefile", line 30, in __rule_merge_results
  File "/home/pelmo/anaconda3/envs/snakemake/lib/python3.9/site-packages/snakemake/executors/__init__.py", line 560, in _callback
  File "/home/pelmo/anaconda3/envs/snakemake/lib/python3.9/concurrent/futures/thread.py", line 52, in run
  File "/home/pelmo/anaconda3/envs/snakemake/lib/python3.9/site-packages/snakemake/executors/__init__.py", line 546, in cached_or_run
  File "/home/pelmo/anaconda3/envs/snakemake/lib/python3.9/site-packages/snakemake/executors/__init__.py", line 2304, in run_wrapper
[Mon Nov 23 15:04:20 2020]
Error in rule merge_results:
    jobid: 87
    output: data/remapped_vars/ENSSSCG00000001404.remapped, data/unmapped_vars/ENSSSCG00000001404.unmapped

RuleException:
CalledProcessError in line 30 of /home/pelmo/sscrofa_variant_remapping/Snakefile:
Command 'set -euo pipefail;  /home/pelmo/anaconda3/envs/snakemake/bin/python3.9 /home/pelmo/sscrofa_variant_remapping/.snakemake/scripts/tmpd_cr6wkt.merge_results.py' returned non-zero exit status 1.
  File "/home/pelmo/anaconda3/envs/snakemake/lib/python3.9/site-packages/snakemake/executors/__init__.py", line 2273, in run_wrapper
  File "/home/pelmo/sscrofa_variant_remapping/Snakefile", line 30, in __rule_merge_results
  File "/home/pelmo/anaconda3/envs/snakemake/lib/python3.9/site-packages/snakemake/executors/__init__.py", line 560, in _callback
  File "/home/pelmo/anaconda3/envs/snakemake/lib/python3.9/concurrent/futures/thread.py", line 52, in run
  File "/home/pelmo/anaconda3/envs/snakemake/lib/python3.9/site-packages/snakemake/executors/__init__.py", line 546, in cached_or_run
  File "/home/pelmo/anaconda3/envs/snakemake/lib/python3.9/site-packages/snakemake/executors/__init__.py", line 2304, in run_wrapper
[Mon Nov 23 15:04:20 2020]
Error in rule merge_results:
    jobid: 179
    output: data/remapped_vars/ENSSSCG00000028629.remapped, data/unmapped_vars/ENSSSCG00000028629.unmapped

RuleException:
CalledProcessError in line 30 of /home/pelmo/sscrofa_variant_remapping/Snakefile:
Command 'set -euo pipefail;  /home/pelmo/anaconda3/envs/snakemake/bin/python3.9 /home/pelmo/sscrofa_variant_remapping/.snakemake/scripts/tmpyggqb_iw.merge_results.py' returned non-zero exit status 1.
  File "/home/pelmo/anaconda3/envs/snakemake/lib/python3.9/site-packages/snakemake/executors/__init__.py", line 2273, in run_wrapper
  File "/home/pelmo/sscrofa_variant_remapping/Snakefile", line 30, in __rule_merge_results
  File "/home/pelmo/anaconda3/envs/snakemake/lib/python3.9/site-packages/snakemake/executors/__init__.py", line 560, in _callback
  File "/home/pelmo/anaconda3/envs/snakemake/lib/python3.9/concurrent/futures/thread.py", line 52, in run
  File "/home/pelmo/anaconda3/envs/snakemake/lib/python3.9/site-packages/snakemake/executors/__init__.py", line 546, in cached_or_run
  File "/home/pelmo/anaconda3/envs/snakemake/lib/python3.9/site-packages/snakemake/executors/__init__.py", line 2304, in run_wrapper
[Mon Nov 23 15:04:20 2020]
[Mon Nov 23 15:04:20 2020]
Error in rule merge_results:
Error in rule merge_results:
    jobid: 117
    jobid: 193
[Mon Nov 23 15:04:20 2020]
    output: data/remapped_vars/ENSSSCG00000007217.remapped, data/unmapped_vars/ENSSSCG00000007217.unmapped
    output: data/remapped_vars/ENSSSCG00000027555.remapped, data/unmapped_vars/ENSSSCG00000027555.unmapped
Error in rule merge_results:


    jobid: 267
    output: data/remapped_vars/ENSSSCG00000006924.remapped, data/unmapped_vars/ENSSSCG00000006924.unmapped

RuleException:
CalledProcessError in line 30 of /home/pelmo/sscrofa_variant_remapping/Snakefile:
Command 'set -euo pipefail;  /home/pelmo/anaconda3/envs/snakemake/bin/python3.9 /home/pelmo/sscrofa_variant_remapping/.snakemake/scripts/tmpxtrekz6d.merge_results.py' returned non-zero exit status 1.
  File "/home/pelmo/anaconda3/envs/snakemake/lib/python3.9/site-packages/snakemake/executors/__init__.py", line 2273, in run_wrapper
  File "/home/pelmo/sscrofa_variant_remapping/Snakefile", line 30, in __rule_merge_results
  File "/home/pelmo/anaconda3/envs/snakemake/lib/python3.9/site-packages/snakemake/executors/__init__.py", line 560, in _callback
  File "/home/pelmo/anaconda3/envs/snakemake/lib/python3.9/concurrent/futures/thread.py", line 52, in run
  File "/home/pelmo/anaconda3/envs/snakemake/lib/python3.9/site-packages/snakemake/executors/__init__.py", line 546, in cached_or_run
  File "/home/pelmo/anaconda3/envs/snakemake/lib/python3.9/site-packages/snakemake/executors/__init__.py", line 2304, in run_wrapper
RuleException:
CalledProcessError in line 30 of /home/pelmo/sscrofa_variant_remapping/Snakefile:
Command 'set -euo pipefail;  /home/pelmo/anaconda3/envs/snakemake/bin/python3.9 /home/pelmo/sscrofa_variant_remapping/.snakemake/scripts/tmp0vuj7j7v.merge_results.py' returned non-zero exit status 1.
  File "/home/pelmo/anaconda3/envs/snakemake/lib/python3.9/site-packages/snakemake/executors/__init__.py", line 2273, in run_wrapper
  File "/home/pelmo/sscrofa_variant_remapping/Snakefile", line 30, in __rule_merge_results
  File "/home/pelmo/anaconda3/envs/snakemake/lib/python3.9/site-packages/snakemake/executors/__init__.py", line 560, in _callback
  File "/home/pelmo/anaconda3/envs/snakemake/lib/python3.9/concurrent/futures/thread.py", line 52, in run
  File "/home/pelmo/anaconda3/envs/snakemake/lib/python3.9/site-packages/snakemake/executors/__init__.py", line 546, in cached_or_run
  File "/home/pelmo/anaconda3/envs/snakemake/lib/python3.9/site-packages/snakemake/executors/__init__.py", line 2304, in run_wrapper
RuleException:
CalledProcessError in line 30 of /home/pelmo/sscrofa_variant_remapping/Snakefile:
Command 'set -euo pipefail;  /home/pelmo/anaconda3/envs/snakemake/bin/python3.9 /home/pelmo/sscrofa_variant_remapping/.snakemake/scripts/tmp4ogg9rhj.merge_results.py' returned non-zero exit status 1.
  File "/home/pelmo/anaconda3/envs/snakemake/lib/python3.9/site-packages/snakemake/executors/__init__.py", line 2273, in run_wrapper
  File "/home/pelmo/sscrofa_variant_remapping/Snakefile", line 30, in __rule_merge_results
  File "/home/pelmo/anaconda3/envs/snakemake/lib/python3.9/site-packages/snakemake/executors/__init__.py", line 560, in _callback
  File "/home/pelmo/anaconda3/envs/snakemake/lib/python3.9/concurrent/futures/thread.py", line 52, in run
  File "/home/pelmo/anaconda3/envs/snakemake/lib/python3.9/site-packages/snakemake/executors/__init__.py", line 546, in cached_or_run
  File "/home/pelmo/anaconda3/envs/snakemake/lib/python3.9/site-packages/snakemake/executors/__init__.py", line 2304, in run_wrapper
Shutting down, this might take some time.
Exiting because a job execution failed. Look above for error message
Complete log: /home/pelmo/sscrofa_variant_remapping/.snakemake/log/2020-11-23T150420.146749.snakemake.log
